Workbook

Sheet Riepilogo Generale
A1: RIEPILOGO GENERALE - ore maturate/tolte e % copertura NON compensativa (100% solo se tutti i corsi del percorso sono al 100% nei fogli Dettaglio)
A2: Discente | B2: Codice Fiscale | C2: Percorso Formativo | J2: Totale Ore Maturate | K2: Ore Tolte (totali) | L2: % copertura | M2: Corsi da finire | N2: Quota Retr. al 80% (€/h) | O2: Costo orario contributivo | P2: Finanziamento
A3: ALBA WILLIAM JULIAN PAZ | B3: PZLWLM96A16Z504F | C3: La programmazione - Tecninf - Fondoconoscenza | J3: =IFERROR(INDEX('Aprile 2026'!AH4:AH37,MATCH("PZLWLM96A16Z504F",'Aprile 2026'!B4:B37,0)),0)+IFERROR(INDEX('Maggio 2026'!AI4:AI37,MATCH("PZLWLM96A16Z504F",'Maggio 2026'!B4:B37,0)),0)+IFERROR(INDEX('Giugno 2026'!AH4:AH37,MATCH("PZLWLM96A16Z504F",'Giugno 2026'!B4:B37,0)),0)+IFERROR(INDEX('Luglio 2026'!AI4:AI37,MATCH("PZLWLM96A16Z504F",'Luglio 2026'!B4:B37,0)),0)+IFERROR(INDEX('Agosto 2026'!AI4:AI37,MATCH("PZLWLM96A16Z504F",'Agosto 2026'!B4:B37,0)),0)+IFERROR(INDEX('Settembre 2026'!AH4:AH37,MATCH("PZLWLM96A16Z504F",'Settembre 2026'!B4:B37,0)),0) | K3: =IFERROR(INDEX('Aprile 2026'!AJ4:AJ37,MATCH("PZLWLM96A16Z504F",'Aprile 2026'!B4:B37,0)),0)+IFERROR(INDEX('Maggio 2026'!AK4:AK37,MATCH("PZLWLM96A16Z504F",'Maggio 2026'!B4:B37,0)),0)+IFERROR(INDEX('Giugno 2026'!AJ4:AJ37,MATCH("PZLWLM96A16Z504F",'Giugno 2026'!B4:B37,0)),0)+IFERROR(INDEX('Luglio 2026'!AK4:AK37,MATCH("PZLWLM96A16Z504F",'Luglio 2026'!B4:B37,0)),0)+IFERROR(INDEX('Agosto 2026'!AK4:AK37,MATCH("PZLWLM96A16Z504F",'Agosto 2026'!B4:B37,0)),0)+IFERROR(INDEX('Settembre 2026'!AJ4:AJ37,MATCH("PZLWLM96A16Z504F",'Settembre 2026'!B4:B37,0)),0) | L3: =IF(75=0,0,MIN((J3*24)/150,1)) | M3: GDPR e nuove normative Europee; I sistemi operativi; Linguaggi di programmazione | N3: 9.731453 | O3: 4.8499263 | P3: =(N3+O3)*J3*24
A4: BADII ALESSANDRO | B4: BDALSN01R03H501Z | C4: Big Data - Tecninf - Fondoconoscenza | J4: =IFERROR(INDEX('Aprile 2026'!AH4:AH37,MATCH("BDALSN01R03H501Z",'Aprile 2026'!B4:B37,0)),0)+IFERROR(INDEX('Maggio 2026'!AI4:AI37,MATCH("BDALSN01R03H501Z",'Maggio 2026'!B4:B37,0)),0)+IFERROR(INDEX('Giugno 2026'!AH4:AH37,MATCH("BDALSN01R03H501Z",'Giugno 2026'!B4:B37,0)),0)+IFERROR(INDEX('Luglio 2026'!AI4:AI37,MATCH("BDALSN01R03H501Z",'Luglio 2026'!B4:B37,0)),0)+IFERROR(INDEX('Agosto 2026'!AI4:AI37,MATCH("BDALSN01R03H501Z",'Agosto 2026'!B4:B37,0)),0)+IFERROR(INDEX('Settembre 2026'!AH4:AH37,MATCH("BDALSN01R03H501Z",'Settembre 2026'!B4:B37,0)),0) | K4: =IFERROR(INDEX('Aprile 2026'!AJ4:AJ37,MATCH("BDALSN01R03H501Z",'Aprile 2026'!B4:B37,0)),0)+IFERROR(INDEX('Maggio 2026'!AK4:AK37,MATCH("BDALSN01R03H501Z",'Maggio 2026'!B4:B37,0)),0)+IFERROR(INDEX('Giugno 2026'!AJ4:AJ37,MATCH("BDALSN01R03H501Z",'Giugno 2026'!B4:B37,0)),0)+IFERROR(INDEX('Luglio 2026'!AK4:AK37,MATCH("BDALSN01R03H501Z",'Luglio 2026'!B4:B37,0)),0)+IFERROR(INDEX('Agosto 2026'!AK4:AK37,MATCH("BDALSN01R03H501Z",'Agosto 2026'!B4:B37,0)),0)+IFERROR(INDEX('Settembre 2026'!AJ4:AJ37,MATCH("BDALSN01R03H501Z",'Settembre 2026'!B4:B37,0)),0) | L4: =IF(75=0,0,MIN((J4*24)/150,1)) | M4: I Big data in ambito finanziario; Deep Learning e reti neurali; Sicurezza e Password Management | N4: 9.731453 | O4: 4.8499263 | P4: =(N4+O4)*J4*24
A5: BADINE HICHAM | B5: BDNHHM97H19H501Q | C5: La programmazione - Tecninf - Fondoconoscenza | J5: =IFERROR(INDEX('Aprile 2026'!AH4:AH37,MATCH("BDNHHM97H19H501Q",'Aprile 2026'!B4:B37,0)),0)+IFERROR(INDEX('Maggio 2026'!AI4:AI37,MATCH("BDNHHM97H19H501Q",'Maggio 2026'!B4:B37,0)),0)+IFERROR(INDEX('Giugno 2026'!AH4:AH37,MATCH("BDNHHM97H19H501Q",'Giugno 2026'!B4:B37,0)),0)+IFERROR(INDEX('Luglio 2026'!AI4:AI37,MATCH("BDNHHM97H19H501Q",'Luglio 2026'!B4:B37,0)),0)+IFERROR(INDEX('Agosto 2026'!AI4:AI37,MATCH("BDNHHM97H19H501Q",'Agosto 2026'!B4:B37,0)),0)+IFERROR(INDEX('Settembre 2026'!AH4:AH37,MATCH("BDNHHM97H19H501Q",'Settembre 2026'!B4:B37,0)),0) | K5: =IFERROR(INDEX('Aprile 2026'!AJ4:AJ37,MATCH("BDNHHM97H19H501Q",'Aprile 2026'!B4:B37,0)),0)+IFERROR(INDEX('Maggio 2026'!AK4:AK37,MATCH("BDNHHM97H19H501Q",'Maggio 2026'!B4:B37,0)),0)+IFERROR(INDEX('Giugno 2026'!AJ4:AJ37,MATCH("BDNHHM97H19H501Q",'Giugno 2026'!B4:B37,0)),0)+IFERROR(INDEX('Luglio 2026'!AK4:AK37,MATCH("BDNHHM97H19H501Q",'Luglio 2026'!B4:B37,0)),0)+IFERROR(INDEX('Agosto 2026'!AK4:AK37,MATCH("BDNHHM97H19H501Q",'Agosto 2026'!B4:B37,0)),0)+IFERROR(INDEX('Settembre 2026'!AJ4:AJ37,MATCH("BDNHHM97H19H501Q",'Settembre 2026'!B4:B37,0)),0) | L5: =IF(75=0,0,MIN((J5*24)/150,1)) | M5: Front end base: HTML, CSS, Bootstrap; Front end avanzato: JavaScript e jQuery | N5: 9.731453 | O5: 3.2352984 | P5: =(N5+O5)*J5*24
A6: BECIANI ANDREA | B6: BCNNDR82P16D773D | C6: La programmazione - Tecninf - Fondoconoscenza | J6: =IFERROR(INDEX('Aprile 2026'!AH4:AH37,MATCH("BCNNDR82P16D773D",'Aprile 2026'!B4:B37,0)),0)+IFERROR(INDEX('Maggio 2026'!AI4:AI37,MATCH("BCNNDR82P16D773D",'Maggio 2026'!B4:B37,0)),0)+IFERROR(INDEX('Giugno 2026'!AH4:AH37,MATCH("BCNNDR82P16D773D",'Giugno 2026'!B4:B37,0)),0)+IFERROR(INDEX('Luglio 2026'!AI4:AI37,MATCH("BCNNDR82P16D773D",'Luglio 2026'!B4:B37,0)),0)+IFERROR(INDEX('Agosto 2026'!AI4:AI37,MATCH("BCNNDR82P16D773D",'Agosto 2026'!B4:B37,0)),0)+IFERROR(INDEX('Settembre 2026'!AH4:AH37,MATCH("BCNNDR82P16D773D",'Settembre 2026'!B4:B37,0)),0) | K6: =IFERROR(INDEX('Aprile 2026'!AJ4:AJ37,MATCH("BCNNDR82P16D773D",'Aprile 2026'!B4:B37,0)),0)+IFERROR(INDEX('Maggio 2026'!AK4:AK37,MATCH("BCNNDR82P16D773D",'Maggio 2026'!B4:B37,0)),0)+IFERROR(INDEX('Giugno 2026'!AJ4:AJ37,MATCH("BCNNDR82P16D773D",'Giugno 2026'!B4:B37,0)),0)+IFERROR(INDEX('Luglio 2026'!AK4:AK37,MATCH("BCNNDR82P16D773D",'Luglio 2026'!B4:B37,0)),0)+IFERROR(INDEX('Agosto 2026'!AK4:AK37,MATCH("BCNNDR82P16D773D",'Agosto 2026'!B4:B37,0)),0)+IFERROR(INDEX('Settembre 2026'!AJ4:AJ37,MATCH("BCNNDR82P16D773D",'Settembre 2026'!B4:B37,0)),0) | L6: =IF(75=0,0,MIN((J6*24)/150,1)) | M6: I sistemi operativi; Linguaggi di programmazione; Back end base: Fondamenti di PHP; Back end avanzato: PHP MVC con Laravel | N6: 9.304 | O6: 5.11 | P6: =(N6+O6)*J6*24
A7: BOONTAWEE JUTATIP | B7: BNTJTP78S54Z241U | C7: Project Management per il digitale - Tecninf - Fondoconoscenza | J7: =IFERROR(INDEX('Aprile 2026'!AH4:AH37,MATCH("BNTJTP78S54Z241U",'Aprile 2026'!B4:B37,0)),0)+IFERROR(INDEX('Maggio 2026'!AI4:AI37,MATCH("BNTJTP78S54Z241U",'Maggio 2026'!B4:B37,0)),0)+IFERROR(INDEX('Giugno 2026'!AH4:AH37,MATCH("BNTJTP78S54Z241U",'Giugno 2026'!B4:B37,0)),0)+IFERROR(INDEX('Luglio 2026'!AI4:AI37,MATCH("BNTJTP78S54Z241U",'Luglio 2026'!B4:B37,0)),0)+IFERROR(INDEX('Agosto 2026'!AI4:AI37,MATCH("BNTJTP78S54Z241U",'Agosto 2026'!B4:B37,0)),0)+IFERROR(INDEX('Settembre 2026'!AH4:AH37,MATCH("BNTJTP78S54Z241U",'Settembre 2026'!B4:B37,0)),0) | K7: =IFERROR(INDEX('Aprile 2026'!AJ4:AJ37,MATCH("BNTJTP78S54Z241U",'Aprile 2026'!B4:B37,0)),0)+IFERROR(INDEX('Maggio 2026'!AK4:AK37,MATCH("BNTJTP78S54Z241U",'Maggio 2026'!B4:B37,0)),0)+IFERROR(INDEX('Giugno 2026'!AJ4:AJ37,MATCH("BNTJTP78S54Z241U",'Giugno 2026'!B4:B37,0)),0)+IFERROR(INDEX('Luglio 2026'!AK4:AK37,MATCH("BNTJTP78S54Z241U",'Luglio 2026'!B4:B37,0)),0)+IFERROR(INDEX('Agosto 2026'!AK4:AK37,MATCH("BNTJTP78S54Z241U",'Agosto 2026'!B4:B37,0)),0)+IFERROR(INDEX('Settembre 2026'!AJ4:AJ37,MATCH("BNTJTP78S54Z241U",'Settembre 2026'!B4:B37,0)),0) | L7: =IF(75=0,0,MIN((J7*24)/150,1)) | M7: La gestione delle risorse umane; La swot analysis del personale; Fondamenti di Project Management; Leadership e Motivazione; Skills e competenze per comunicare in azienda | N7: 13.178009 | O7: 6.5675808 | P7: =(N7+O7)*J7*24
A8: BUTTINELLI GIORGIA | B8: BTTGRG97S59G274Q | C8: Big Data - Tecninf - Fondoconoscenza | J8: =IFERROR(INDEX('Aprile 2026'!AH4:AH37,MATCH("BTTGRG97S59G274Q",'Aprile 2026'!B4:B37,0)),0)+IFERROR(INDEX('Maggio 2026'!AI4:AI37,MATCH("BTTGRG97S59G274Q",'Maggio 2026'!B4:B37,0)),0)+IFERROR(INDEX('Giugno 2026'!AH4:AH37,MATCH("BTTGRG97S59G274Q",'Giugno 2026'!B4:B37,0)),0)+IFERROR(INDEX('Luglio 2026'!AI4:AI37,MATCH("BTTGRG97S59G274Q",'Luglio 2026'!B4:B37,0)),0)+IFERROR(INDEX('Agosto 2026'!AI4:AI37,MATCH("BTTGRG97S59G274Q",'Agosto 2026'!B4:B37,0)),0)+IFERROR(INDEX('Settembre 2026'!AH4:AH37,MATCH("BTTGRG97S59G274Q",'Settembre 2026'!B4:B37,0)),0) | K8: =IFERROR(INDEX('Aprile 2026'!AJ4:AJ37,MATCH("BTTGRG97S59G274Q",'Aprile 2026'!B4:B37,0)),0)+IFERROR(INDEX('Maggio 2026'!AK4:AK37,MATCH("BTTGRG97S59G274Q",'Maggio 2026'!B4:B37,0)),0)+IFERROR(INDEX('Giugno 2026'!AJ4:AJ37,MATCH("BTTGRG97S59G274Q",'Giugno 2026'!B4:B37,0)),0)+IFERROR(INDEX('Luglio 2026'!AK4:AK37,MATCH("BTTGRG97S59G274Q",'Luglio 2026'!B4:B37,0)),0)+IFERROR(INDEX('Agosto 2026'!AK4:AK37,MATCH("BTTGRG97S59G274Q",'Agosto 2026'!B4:B37,0)),0)+IFERROR(INDEX('Settembre 2026'!AJ4:AJ37,MATCH("BTTGRG97S59G274Q",'Settembre 2026'!B4:B37,0)),0) | L8: =IF(75=0,0,MIN((J8*24)/150,1)) | M8: GDPR e nuove normative Europee; Introduzione ai Big Data nelle aziende; Big data e analisi predittiva; I Big data in ambito finanziario; Database relazionali e linguaggio SQL con PHP; Natural Language Processing con Python; Progettare autorizzazioni e autentificazioni; Gestione avanzata di un Database | N8: 9.9848763 | O8: 4.9762074 | P8: =(N8+O8)*J8*24
A9: CARABLUT VICTOR | B9: CRBVTR94A11Z140B | C9: Sicurezza Informatica - Tecninf - Fondoconoscenza | J9: =IFERROR(INDEX('Aprile 2026'!AH4:AH37,MATCH("CRBVTR94A11Z140B",'Aprile 2026'!B4:B37,0)),0)+IFERROR(INDEX('Maggio 2026'!AI4:AI37,MATCH("CRBVTR94A11Z140B",'Maggio 2026'!B4:B37,0)),0)+IFERROR(INDEX('Giugno 2026'!AH4:AH37,MATCH("CRBVTR94A11Z140B",'Giugno 2026'!B4:B37,0)),0)+IFERROR(INDEX('Luglio 2026'!AI4:AI37,MATCH("CRBVTR94A11Z140B",'Luglio 2026'!B4:B37,0)),0)+IFERROR(INDEX('Agosto 2026'!AI4:AI37,MATCH("CRBVTR94A11Z140B",'Agosto 2026'!B4:B37,0)),0)+IFERROR(INDEX('Settembre 2026'!AH4:AH37,MATCH("CRBVTR94A11Z140B",'Settembre 2026'!B4:B37,0)),0) | K9: =IFERROR(INDEX('Aprile 2026'!AJ4:AJ37,MATCH("CRBVTR94A11Z140B",'Aprile 2026'!B4:B37,0)),0)+IFERROR(INDEX('Maggio 2026'!AK4:AK37,MATCH("CRBVTR94A11Z140B",'Maggio 2026'!B4:B37,0)),0)+IFERROR(INDEX('Giugno 2026'!AJ4:AJ37,MATCH("CRBVTR94A11Z140B",'Giugno 2026'!B4:B37,0)),0)+IFERROR(INDEX('Luglio 2026'!AK4:AK37,MATCH("CRBVTR94A11Z140B",'Luglio 2026'!B4:B37,0)),0)+IFERROR(INDEX('Agosto 2026'!AK4:AK37,MATCH("CRBVTR94A11Z140B",'Agosto 2026'!B4:B37,0)),0)+IFERROR(INDEX('Settembre 2026'!AJ4:AJ37,MATCH("CRBVTR94A11Z140B",'Settembre 2026'!B4:B37,0)),0) | L9: =IF(75=0,0,MIN((J9*24)/150,1)) | M9: GDPR e nuove normative Europee; La Cyber Security; La Network Security; Cloud e Fog Computing; I sistemi cyber fisici; Internet delle Cose e delle Macchine; Gli attacchi tramite Ransomware | N9: 9.8581647 | O9: 4.9130133 | P9: =(N9+O9)*J9*24
A10: CECCONI ANTHONY | B10: CCCNHN91D19H501W | C10: La programmazione - Tecninf - Fondoconoscenza | J10: =IFERROR(INDEX('Aprile 2026'!AH4:AH37,MATCH("CCCNHN91D19H501W",'Aprile 2026'!B4:B37,0)),0)+IFERROR(INDEX('Maggio 2026'!AI4:AI37,MATCH("CCCNHN91D19H501W",'Maggio 2026'!B4:B37,0)),0)+IFERROR(INDEX('Giugno 2026'!AH4:AH37,MATCH("CCCNHN91D19H501W",'Giugno 2026'!B4:B37,0)),0)+IFERROR(INDEX('Luglio 2026'!AI4:AI37,MATCH("CCCNHN91D19H501W",'Luglio 2026'!B4:B37,0)),0)+IFERROR(INDEX('Agosto 2026'!AI4:AI37,MATCH("CCCNHN91D19H501W",'Agosto 2026'!B4:B37,0)),0)+IFERROR(INDEX('Settembre 2026'!AH4:AH37,MATCH("CCCNHN91D19H501W",'Settembre 2026'!B4:B37,0)),0) | K10: =IFERROR(INDEX('Aprile 2026'!AJ4:AJ37,MATCH("CCCNHN91D19H501W",'Aprile 2026'!B4:B37,0)),0)+IFERROR(INDEX('Maggio 2026'!AK4:AK37,MATCH("CCCNHN91D19H501W",'Maggio 2026'!B4:B37,0)),0)+IFERROR(INDEX('Giugno 2026'!AJ4:AJ37,MATCH("CCCNHN91D19H501W",'Giugno 2026'!B4:B37,0)),0)+IFERROR(INDEX('Luglio 2026'!AK4:AK37,MATCH("CCCNHN91D19H501W",'Luglio 2026'!B4:B37,0)),0)+IFERROR(INDEX('Agosto 2026'!AK4:AK37,MATCH("CCCNHN91D19H501W",'Agosto 2026'!B4:B37,0)),0)+IFERROR(INDEX('Settembre 2026'!AJ4:AJ37,MATCH("CCCNHN91D19H501W",'Settembre 2026'!B4:B37,0)),0) | L10: =IF(75=0,0,MIN((J10*24)/150,1)) | M10: GDPR e nuove normative Europee; I sistemi operativi; Applicazioni dinamiche con PHP e MySql; Back end avanzato: PHP MVC con Laravel | N10: 9.731453 | O10: 4.8499263 | P10: =(N10+O10)*J10*24
A11: CHIARA GOBBI MARIA | B11: GBBMCH73R57H501G | C11: L'ufficio digitale - Tecninf - Fondoconoscenza | J11: =IFERROR(INDEX('Aprile 2026'!AH4:AH37,MATCH("GBBMCH73R57H501G",'Aprile 2026'!B4:B37,0)),0)+IFERROR(INDEX('Maggio 2026'!AI4:AI37,MATCH("GBBMCH73R57H501G",'Maggio 2026'!B4:B37,0)),0)+IFERROR(INDEX('Giugno 2026'!AH4:AH37,MATCH("GBBMCH73R57H501G",'Giugno 2026'!B4:B37,0)),0)+IFERROR(INDEX('Luglio 2026'!AI4:AI37,MATCH("GBBMCH73R57H501G",'Luglio 2026'!B4:B37,0)),0)+IFERROR(INDEX('Agosto 2026'!AI4:AI37,MATCH("GBBMCH73R57H501G",'Agosto 2026'!B4:B37,0)),0)+IFERROR(INDEX('Settembre 2026'!AH4:AH37,MATCH("GBBMCH73R57H501G",'Settembre 2026'!B4:B37,0)),0) | K11: =IFERROR(INDEX('Aprile 2026'!AJ4:AJ37,MATCH("GBBMCH73R57H501G",'Aprile 2026'!B4:B37,0)),0)+IFERROR(INDEX('Maggio 2026'!AK4:AK37,MATCH("GBBMCH73R57H501G",'Maggio 2026'!B4:B37,0)),0)+IFERROR(INDEX('Giugno 2026'!AJ4:AJ37,MATCH("GBBMCH73R57H501G",'Giugno 2026'!B4:B37,0)),0)+IFERROR(INDEX('Luglio 2026'!AK4:AK37,MATCH("GBBMCH73R57H501G",'Luglio 2026'!B4:B37,0)),0)+IFERROR(INDEX('Agosto 2026'!AK4:AK37,MATCH("GBBMCH73R57H501G",'Agosto 2026'!B4:B37,0)),0)+IFERROR(INDEX('Settembre 2026'!AJ4:AJ37,MATCH("GBBMCH73R57H501G",'Settembre 2026'!B4:B37,0)),0) | L11: =IF(75=0,0,MIN((J11*24)/150,1)) | M11: GDPR e nuove normative Europee; Introduzione al mondo di Microsoft office 365; Microsoft 365: Outlook desktop corso completo; Microsoft 365: Data Modeling con Power Query; Microsoft 365: elementi avanzati, suggerimenti e trucchi in PowerPoint; I sistemi informatici | N11: 12.31637 | O11: 6.1381456 | P11: =(N11+O11)*J11*24
A12: LIMETTI ION | B12: LMTNIO94M03Z129S | C12: Big Data - Tecninf - Fondoconoscenza | J12: =IFERROR(INDEX('Aprile 2026'!AH4:AH37,MATCH("LMTNIO94M03Z129S",'Aprile 2026'!B4:B37,0)),0)+IFERROR(INDEX('Maggio 2026'!AI4:AI37,MATCH("LMTNIO94M03Z129S",'Maggio 2026'!B4:B37,0)),0)+IFERROR(INDEX('Giugno 2026'!AH4:AH37,MATCH("LMTNIO94M03Z129S",'Giugno 2026'!B4:B37,0)),0)+IFERROR(INDEX('Luglio 2026'!AI4:AI37,MATCH("LMTNIO94M03Z129S",'Luglio 2026'!B4:B37,0)),0)+IFERROR(INDEX('Agosto 2026'!AI4:AI37,MATCH("LMTNIO94M03Z129S",'Agosto 2026'!B4:B37,0)),0)+IFERROR(INDEX('Settembre 2026'!AH4:AH37,MATCH("LMTNIO94M03Z129S",'Settembre 2026'!B4:B37,0)),0) | K12: =IFERROR(INDEX('Aprile 2026'!AJ4:AJ37,MATCH("LMTNIO94M03Z129S",'Aprile 2026'!B4:B37,0)),0)+IFERROR(INDEX('Maggio 2026'!AK4:AK37,MATCH("LMTNIO94M03Z129S",'Maggio 2026'!B4:B37,0)),0)+IFERROR(INDEX('Giugno 2026'!AJ4:AJ37,MATCH("LMTNIO94M03Z129S",'Giugno 2026'!B4:B37,0)),0)+IFERROR(INDEX('Luglio 2026'!AK4:AK37,MATCH("LMTNIO94M03Z129S",'Luglio 2026'!B4:B37,0)),0)+IFERROR(INDEX('Agosto 2026'!AK4:AK37,MATCH("LMTNIO94M03Z129S",'Agosto 2026'!B4:B37,0)),0)+IFERROR(INDEX('Settembre 2026'!AJ4:AJ37,MATCH("LMTNIO94M03Z129S",'Settembre 2026'!B4:B37,0)),0) | L12: =IF(75=0,0,MIN((J12*24)/150,1)) | M12: GDPR e nuove normative Europee; Big data e analisi predittiva; I Big data in ambito finanziario; Natural Language Processing con Python; Big Data Analytics con Python e Spark | N12: 10.876926 | O12: 5.4207553 | P12: =(N12+O12)*J12*24
A13: LUCA' VERONICA | B13: LCUVNC85L52D976T | C13: Big Data - Tecninf - Fondoconoscenza | J13: =IFERROR(INDEX('Aprile 2026'!AH4:AH37,MATCH("LCUVNC85L52D976T",'Aprile 2026'!B4:B37,0)),0)+IFERROR(INDEX('Maggio 2026'!AI4:AI37,MATCH("LCUVNC85L52D976T",'Maggio 2026'!B4:B37,0)),0)+IFERROR(INDEX('Giugno 2026'!AH4:AH37,MATCH("LCUVNC85L52D976T",'Giugno 2026'!B4:B37,0)),0)+IFERROR(INDEX('Luglio 2026'!AI4:AI37,MATCH("LCUVNC85L52D976T",'Luglio 2026'!B4:B37,0)),0)+IFERROR(INDEX('Agosto 2026'!AI4:AI37,MATCH("LCUVNC85L52D976T",'Agosto 2026'!B4:B37,0)),0)+IFERROR(INDEX('Settembre 2026'!AH4:AH37,MATCH("LCUVNC85L52D976T",'Settembre 2026'!B4:B37,0)),0) | K13: =IFERROR(INDEX('Aprile 2026'!AJ4:AJ37,MATCH("LCUVNC85L52D976T",'Aprile 2026'!B4:B37,0)),0)+IFERROR(INDEX('Maggio 2026'!AK4:AK37,MATCH("LCUVNC85L52D976T",'Maggio 2026'!B4:B37,0)),0)+IFERROR(INDEX('Giugno 2026'!AJ4:AJ37,MATCH("LCUVNC85L52D976T",'Giugno 2026'!B4:B37,0)),0)+IFERROR(INDEX('Luglio 2026'!AK4:AK37,MATCH("LCUVNC85L52D976T",'Luglio 2026'!B4:B37,0)),0)+IFERROR(INDEX('Agosto 2026'!AK4:AK37,MATCH("LCUVNC85L52D976T",'Agosto 2026'!B4:B37,0)),0)+IFERROR(INDEX('Settembre 2026'!AJ4:AJ37,MATCH("LCUVNC85L52D976T",'Settembre 2026'!B4:B37,0)),0) | L13: =IF(75=0,0,MIN((J13*24)/150,1)) | M13: Big data e analisi predittiva | N13: 10.425833 | O13: 3.783118 | P13: =(N13+O13)*J13*24
A14: MAGNANINI LORENZO | B14: MGNLNZ97M04H501T | C14: La programmazione - Tecninf - Fondoconoscenza | J14: =IFERROR(INDEX('Aprile 2026'!AH4:AH37,MATCH("MGNLNZ97M04H501T",'Aprile 2026'!B4:B37,0)),0)+IFERROR(INDEX('Maggio 2026'!AI4:AI37,MATCH("MGNLNZ97M04H501T",'Maggio 2026'!B4:B37,0)),0)+IFERROR(INDEX('Giugno 2026'!AH4:AH37,MATCH("MGNLNZ97M04H501T",'Giugno 2026'!B4:B37,0)),0)+IFERROR(INDEX('Luglio 2026'!AI4:AI37,MATCH("MGNLNZ97M04H501T",'Luglio 2026'!B4:B37,0)),0)+IFERROR(INDEX('Agosto 2026'!AI4:AI37,MATCH("MGNLNZ97M04H501T",'Agosto 2026'!B4:B37,0)),0)+IFERROR(INDEX('Settembre 2026'!AH4:AH37,MATCH("MGNLNZ97M04H501T",'Settembre 2026'!B4:B37,0)),0) | K14: =IFERROR(INDEX('Aprile 2026'!AJ4:AJ37,MATCH("MGNLNZ97M04H501T",'Aprile 2026'!B4:B37,0)),0)+IFERROR(INDEX('Maggio 2026'!AK4:AK37,MATCH("MGNLNZ97M04H501T",'Maggio 2026'!B4:B37,0)),0)+IFERROR(INDEX('Giugno 2026'!AJ4:AJ37,MATCH("MGNLNZ97M04H501T",'Giugno 2026'!B4:B37,0)),0)+IFERROR(INDEX('Luglio 2026'!AK4:AK37,MATCH("MGNLNZ97M04H501T",'Luglio 2026'!B4:B37,0)),0)+IFERROR(INDEX('Agosto 2026'!AK4:AK37,MATCH("MGNLNZ97M04H501T",'Agosto 2026'!B4:B37,0)),0)+IFERROR(INDEX('Settembre 2026'!AJ4:AJ37,MATCH("MGNLNZ97M04H501T",'Settembre 2026'!B4:B37,0)),0) | L14: =IF(75=0,0,MIN((J14*24)/150,1)) | M14: I sistemi operativi; Front end base: HTML, CSS, Bootstrap; Front end avanzato: JavaScript e jQuery; Back end base: Fondamenti di PHP; Database relazionali e linguaggio SQL con PHP; Applicazioni dinamiche con PHP e MySql | N14: 9.731453 | O14: 4.7831589 | P14: =(N14+O14)*J14*24
A15: MARIANI ALESSIA | B15: MRNLSS75L68H501L | C15: Big Data - Tecninf - Fondoconoscenza | J15: =IFERROR(INDEX('Aprile 2026'!AH4:AH37,MATCH("MRNLSS75L68H501L",'Aprile 2026'!B4:B37,0)),0)+IFERROR(INDEX('Maggio 2026'!AI4:AI37,MATCH("MRNLSS75L68H501L",'Maggio 2026'!B4:B37,0)),0)+IFERROR(INDEX('Giugno 2026'!AH4:AH37,MATCH("MRNLSS75L68H501L",'Giugno 2026'!B4:B37,0)),0)+IFERROR(INDEX('Luglio 2026'!AI4:AI37,MATCH("MRNLSS75L68H501L",'Luglio 2026'!B4:B37,0)),0)+IFERROR(INDEX('Agosto 2026'!AI4:AI37,MATCH("MRNLSS75L68H501L",'Agosto 2026'!B4:B37,0)),0)+IFERROR(INDEX('Settembre 2026'!AH4:AH37,MATCH("MRNLSS75L68H501L",'Settembre 2026'!B4:B37,0)),0) | K15: =IFERROR(INDEX('Aprile 2026'!AJ4:AJ37,MATCH("MRNLSS75L68H501L",'Aprile 2026'!B4:B37,0)),0)+IFERROR(INDEX('Maggio 2026'!AK4:AK37,MATCH("MRNLSS75L68H501L",'Maggio 2026'!B4:B37,0)),0)+IFERROR(INDEX('Giugno 2026'!AJ4:AJ37,MATCH("MRNLSS75L68H501L",'Giugno 2026'!B4:B37,0)),0)+IFERROR(INDEX('Luglio 2026'!AK4:AK37,MATCH("MRNLSS75L68H501L",'Luglio 2026'!B4:B37,0)),0)+IFERROR(INDEX('Agosto 2026'!AK4:AK37,MATCH("MRNLSS75L68H501L",'Agosto 2026'!B4:B37,0)),0)+IFERROR(INDEX('Settembre 2026'!AJ4:AJ37,MATCH("MRNLSS75L68H501L",'Settembre 2026'!B4:B37,0)),0) | L15: =IF(75=0,0,MIN((J15*24)/150,1)) | M15: GDPR e nuove normative Europee; Big data e analisi predittiva; Business Intelligence e analisi predittiva; Database relazionali e linguaggio SQL con PHP; Il Machine Learning con Python; Big Data Analytics con Python e Spark | N15: 10.876926 | O15: 5.3461739 | P15: =(N15+O15)*J15*24
A16: MASCELLINO GIULIO | B16: MSCGLI83C04G511L | C16: Big Data - Tecninf - Fondoconoscenza | J16: =IFERROR(INDEX('Aprile 2026'!AH4:AH37,MATCH("MSCGLI83C04G511L",'Aprile 2026'!B4:B37,0)),0)+IFERROR(INDEX('Maggio 2026'!AI4:AI37,MATCH("MSCGLI83C04G511L",'Maggio 2026'!B4:B37,0)),0)+IFERROR(INDEX('Giugno 2026'!AH4:AH37,MATCH("MSCGLI83C04G511L",'Giugno 2026'!B4:B37,0)),0)+IFERROR(INDEX('Luglio 2026'!AI4:AI37,MATCH("MSCGLI83C04G511L",'Luglio 2026'!B4:B37,0)),0)+IFERROR(INDEX('Agosto 2026'!AI4:AI37,MATCH("MSCGLI83C04G511L",'Agosto 2026'!B4:B37,0)),0)+IFERROR(INDEX('Settembre 2026'!AH4:AH37,MATCH("MSCGLI83C04G511L",'Settembre 2026'!B4:B37,0)),0) | K16: =IFERROR(INDEX('Aprile 2026'!AJ4:AJ37,MATCH("MSCGLI83C04G511L",'Aprile 2026'!B4:B37,0)),0)+IFERROR(INDEX('Maggio 2026'!AK4:AK37,MATCH("MSCGLI83C04G511L",'Maggio 2026'!B4:B37,0)),0)+IFERROR(INDEX('Giugno 2026'!AJ4:AJ37,MATCH("MSCGLI83C04G511L",'Giugno 2026'!B4:B37,0)),0)+IFERROR(INDEX('Luglio 2026'!AK4:AK37,MATCH("MSCGLI83C04G511L",'Luglio 2026'!B4:B37,0)),0)+IFERROR(INDEX('Agosto 2026'!AK4:AK37,MATCH("MSCGLI83C04G511L",'Agosto 2026'!B4:B37,0)),0)+IFERROR(INDEX('Settembre 2026'!AJ4:AJ37,MATCH("MSCGLI83C04G511L",'Settembre 2026'!B4:B37,0)),0) | L16: =IF(75=0,0,MIN((J16*24)/150,1)) | M16: Big data e analisi predittiva | N16: 19.584 | O16: 8.85 | P16: =(N16+O16)*J16*24
A17: PACPACO MICHAEL DEPOLLY | B17: PCPMHL00R03H501G | C17: La programmazione - Tecninf - Fondoconoscenza | J17: =IFERROR(INDEX('Aprile 2026'!AH4:AH37,MATCH("PCPMHL00R03H501G",'Aprile 2026'!B4:B37,0)),0)+IFERROR(INDEX('Maggio 2026'!AI4:AI37,MATCH("PCPMHL00R03H501G",'Maggio 2026'!B4:B37,0)),0)+IFERROR(INDEX('Giugno 2026'!AH4:AH37,MATCH("PCPMHL00R03H501G",'Giugno 2026'!B4:B37,0)),0)+IFERROR(INDEX('Luglio 2026'!AI4:AI37,MATCH("PCPMHL00R03H501G",'Luglio 2026'!B4:B37,0)),0)+IFERROR(INDEX('Agosto 2026'!AI4:AI37,MATCH("PCPMHL00R03H501G",'Agosto 2026'!B4:B37,0)),0)+IFERROR(INDEX('Settembre 2026'!AH4:AH37,MATCH("PCPMHL00R03H501G",'Settembre 2026'!B4:B37,0)),0) | K17: =IFERROR(INDEX('Aprile 2026'!AJ4:AJ37,MATCH("PCPMHL00R03H501G",'Aprile 2026'!B4:B37,0)),0)+IFERROR(INDEX('Maggio 2026'!AK4:AK37,MATCH("PCPMHL00R03H501G",'Maggio 2026'!B4:B37,0)),0)+IFERROR(INDEX('Giugno 2026'!AJ4:AJ37,MATCH("PCPMHL00R03H501G",'Giugno 2026'!B4:B37,0)),0)+IFERROR(INDEX('Luglio 2026'!AK4:AK37,MATCH("PCPMHL00R03H501G",'Luglio 2026'!B4:B37,0)),0)+IFERROR(INDEX('Agosto 2026'!AK4:AK37,MATCH("PCPMHL00R03H501G",'Agosto 2026'!B4:B37,0)),0)+IFERROR(INDEX('Settembre 2026'!AJ4:AJ37,MATCH("PCPMHL00R03H501G",'Settembre 2026'!B4:B37,0)),0) | L17: =IF(75=0,0,MIN((J17*24)/150,1)) | M17: GDPR e nuove normative Europee; Linguaggi di programmazione; Back end base: Fondamenti di PHP; Applicazioni dinamiche con PHP e MySql | N17: 8.7460465 | O17: 2.0936329 | P17: =(N17+O17)*J17*24
A18: PASSIO ROBERTA | B18: PSSRRT76L56H501O | C18: Sicurezza Informatica - Tecninf - Fondoconoscenza | J18: =IFERROR(INDEX('Aprile 2026'!AH4:AH37,MATCH("PSSRRT76L56H501O",'Aprile 2026'!B4:B37,0)),0)+IFERROR(INDEX('Maggio 2026'!AI4:AI37,MATCH("PSSRRT76L56H501O",'Maggio 2026'!B4:B37,0)),0)+IFERROR(INDEX('Giugno 2026'!AH4:AH37,MATCH("PSSRRT76L56H501O",'Giugno 2026'!B4:B37,0)),0)+IFERROR(INDEX('Luglio 2026'!AI4:AI37,MATCH("PSSRRT76L56H501O",'Luglio 2026'!B4:B37,0)),0)+IFERROR(INDEX('Agosto 2026'!AI4:AI37,MATCH("PSSRRT76L56H501O",'Agosto 2026'!B4:B37,0)),0)+IFERROR(INDEX('Settembre 2026'!AH4:AH37,MATCH("PSSRRT76L56H501O",'Settembre 2026'!B4:B37,0)),0) | K18: =IFERROR(INDEX('Aprile 2026'!AJ4:AJ37,MATCH("PSSRRT76L56H501O",'Aprile 2026'!B4:B37,0)),0)+IFERROR(INDEX('Maggio 2026'!AK4:AK37,MATCH("PSSRRT76L56H501O",'Maggio 2026'!B4:B37,0)),0)+IFERROR(INDEX('Giugno 2026'!AJ4:AJ37,MATCH("PSSRRT76L56H501O",'Giugno 2026'!B4:B37,0)),0)+IFERROR(INDEX('Luglio 2026'!AK4:AK37,MATCH("PSSRRT76L56H501O",'Luglio 2026'!B4:B37,0)),0)+IFERROR(INDEX('Agosto 2026'!AK4:AK37,MATCH("PSSRRT76L56H501O",'Agosto 2026'!B4:B37,0)),0)+IFERROR(INDEX('Settembre 2026'!AJ4:AJ37,MATCH("PSSRRT76L56H501O",'Settembre 2026'!B4:B37,0)),0) | L18: =IF(75=0,0,MIN((J18*24)/150,1)) | M18: GDPR e nuove normative Europee; Elementi base di sicurezza informatica; Virus e Antivirus per tutti; La Cyber Security; La Network Security; Cloud e Fog Computing; I sistemi cyber fisici; Internet delle Cose e delle Macchine; Gli attacchi tramite Ransomware | N18: 12.31637 | O18: 6.1381456 | P18: =(N18+O18)*J18*24
A19: PERILLA GIAN LEO GAMES | B19: PRLGLG98M18H501X | C19: Big Data - Tecninf - Fondoconoscenza | J19: =IFERROR(INDEX('Aprile 2026'!AH4:AH37,MATCH("PRLGLG98M18H501X",'Aprile 2026'!B4:B37,0)),0)+IFERROR(INDEX('Maggio 2026'!AI4:AI37,MATCH("PRLGLG98M18H501X",'Maggio 2026'!B4:B37,0)),0)+IFERROR(INDEX('Giugno 2026'!AH4:AH37,MATCH("PRLGLG98M18H501X",'Giugno 2026'!B4:B37,0)),0)+IFERROR(INDEX('Luglio 2026'!AI4:AI37,MATCH("PRLGLG98M18H501X",'Luglio 2026'!B4:B37,0)),0)+IFERROR(INDEX('Agosto 2026'!AI4:AI37,MATCH("PRLGLG98M18H501X",'Agosto 2026'!B4:B37,0)),0)+IFERROR(INDEX('Settembre 2026'!AH4:AH37,MATCH("PRLGLG98M18H501X",'Settembre 2026'!B4:B37,0)),0) | K19: =IFERROR(INDEX('Aprile 2026'!AJ4:AJ37,MATCH("PRLGLG98M18H501X",'Aprile 2026'!B4:B37,0)),0)+IFERROR(INDEX('Maggio 2026'!AK4:AK37,MATCH("PRLGLG98M18H501X",'Maggio 2026'!B4:B37,0)),0)+IFERROR(INDEX('Giugno 2026'!AJ4:AJ37,MATCH("PRLGLG98M18H501X",'Giugno 2026'!B4:B37,0)),0)+IFERROR(INDEX('Luglio 2026'!AK4:AK37,MATCH("PRLGLG98M18H501X",'Luglio 2026'!B4:B37,0)),0)+IFERROR(INDEX('Agosto 2026'!AK4:AK37,MATCH("PRLGLG98M18H501X",'Agosto 2026'!B4:B37,0)),0)+IFERROR(INDEX('Settembre 2026'!AJ4:AJ37,MATCH("PRLGLG98M18H501X",'Settembre 2026'!B4:B37,0)),0) | L19: =IF(75=0,0,MIN((J19*24)/150,1)) | M19: Sicurezza e Password Management | N19: 9.731453 | O19: 4.8499074 | P19: =(N19+O19)*J19*24
A20: PINNA ROBERTO CAO | B20: CPNRRT66D27H501V | C20: Project Management per il digitale - Tecninf - Fondoconoscenza | J20: =IFERROR(INDEX('Aprile 2026'!AH4:AH37,MATCH("CPNRRT66D27H501V",'Aprile 2026'!B4:B37,0)),0)+IFERROR(INDEX('Maggio 2026'!AI4:AI37,MATCH("CPNRRT66D27H501V",'Maggio 2026'!B4:B37,0)),0)+IFERROR(INDEX('Giugno 2026'!AH4:AH37,MATCH("CPNRRT66D27H501V",'Giugno 2026'!B4:B37,0)),0)+IFERROR(INDEX('Luglio 2026'!AI4:AI37,MATCH("CPNRRT66D27H501V",'Luglio 2026'!B4:B37,0)),0)+IFERROR(INDEX('Agosto 2026'!AI4:AI37,MATCH("CPNRRT66D27H501V",'Agosto 2026'!B4:B37,0)),0)+IFERROR(INDEX('Settembre 2026'!AH4:AH37,MATCH("CPNRRT66D27H501V",'Settembre 2026'!B4:B37,0)),0) | K20: =IFERROR(INDEX('Aprile 2026'!AJ4:AJ37,MATCH("CPNRRT66D27H501V",'Aprile 2026'!B4:B37,0)),0)+IFERROR(INDEX('Maggio 2026'!AK4:AK37,MATCH("CPNRRT66D27H501V",'Maggio 2026'!B4:B37,0)),0)+IFERROR(INDEX('Giugno 2026'!AJ4:AJ37,MATCH("CPNRRT66D27H501V",'Giugno 2026'!B4:B37,0)),0)+IFERROR(INDEX('Luglio 2026'!AK4:AK37,MATCH("CPNRRT66D27H501V",'Luglio 2026'!B4:B37,0)),0)+IFERROR(INDEX('Agosto 2026'!AK4:AK37,MATCH("CPNRRT66D27H501V",'Agosto 2026'!B4:B37,0)),0)+IFERROR(INDEX('Settembre 2026'!AJ4:AJ37,MATCH("CPNRRT66D27H501V",'Settembre 2026'!B4:B37,0)),0) | L20: =IF(75=0,0,MIN((J20*24)/150,1)) | M20: Ottimizzare ed organizzare i meeting online; Gli approcci nel Problem Solving; Comprensione di una struttura organizzativa; Guidare un team con l'intelligenza emotiva; Fondamenti di Project Management; Predictive-Waterfall e lo sviluppo di un progetto; Comunicazione aziendale e risoluzione dei conflitti; Skills e competenze per comunicare in azienda | N20: 14.36403 | O20: 7.1586761 | P20: =(N20+O20)*J20*24
A21: POGGI ROBERTO | B21: PGGRRT91H07F839Q | C21: Big Data - Tecninf - Fondoconoscenza | J21: =IFERROR(INDEX('Aprile 2026'!AH4:AH37,MATCH("PGGRRT91H07F839Q",'Aprile 2026'!B4:B37,0)),0)+IFERROR(INDEX('Maggio 2026'!AI4:AI37,MATCH("PGGRRT91H07F839Q",'Maggio 2026'!B4:B37,0)),0)+IFERROR(INDEX('Giugno 2026'!AH4:AH37,MATCH("PGGRRT91H07F839Q",'Giugno 2026'!B4:B37,0)),0)+IFERROR(INDEX('Luglio 2026'!AI4:AI37,MATCH("PGGRRT91H07F839Q",'Luglio 2026'!B4:B37,0)),0)+IFERROR(INDEX('Agosto 2026'!AI4:AI37,MATCH("PGGRRT91H07F839Q",'Agosto 2026'!B4:B37,0)),0)+IFERROR(INDEX('Settembre 2026'!AH4:AH37,MATCH("PGGRRT91H07F839Q",'Settembre 2026'!B4:B37,0)),0) | K21: =IFERROR(INDEX('Aprile 2026'!AJ4:AJ37,MATCH("PGGRRT91H07F839Q",'Aprile 2026'!B4:B37,0)),0)+IFERROR(INDEX('Maggio 2026'!AK4:AK37,MATCH("PGGRRT91H07F839Q",'Maggio 2026'!B4:B37,0)),0)+IFERROR(INDEX('Giugno 2026'!AJ4:AJ37,MATCH("PGGRRT91H07F839Q",'Giugno 2026'!B4:B37,0)),0)+IFERROR(INDEX('Luglio 2026'!AK4:AK37,MATCH("PGGRRT91H07F839Q",'Luglio 2026'!B4:B37,0)),0)+IFERROR(INDEX('Agosto 2026'!AK4:AK37,MATCH("PGGRRT91H07F839Q",'Agosto 2026'!B4:B37,0)),0)+IFERROR(INDEX('Settembre 2026'!AJ4:AJ37,MATCH("PGGRRT91H07F839Q",'Settembre 2026'!B4:B37,0)),0) | L21: =IF(75=0,0,MIN((J21*24)/150,1)) | M21: GDPR e nuove normative Europee; Big Data Analytics con Python e Spark; Progettare autorizzazioni e autentificazioni; Sicurezza e Password Management | N21: 10.876926 | O21: 5.4207553 | P21: =(N21+O21)*J21*24
A22: PRASAD RAKESH KUMAR | B22: PRSRSH87S19H501S | C22: Sicurezza Informatica - Tecninf - Fondoconoscenza | J22: =IFERROR(INDEX('Aprile 2026'!AH4:AH37,MATCH("PRSRSH87S19H501S",'Aprile 2026'!B4:B37,0)),0)+IFERROR(INDEX('Maggio 2026'!AI4:AI37,MATCH("PRSRSH87S19H501S",'Maggio 2026'!B4:B37,0)),0)+IFERROR(INDEX('Giugno 2026'!AH4:AH37,MATCH("PRSRSH87S19H501S",'Giugno 2026'!B4:B37,0)),0)+IFERROR(INDEX('Luglio 2026'!AI4:AI37,MATCH("PRSRSH87S19H501S",'Luglio 2026'!B4:B37,0)),0)+IFERROR(INDEX('Agosto 2026'!AI4:AI37,MATCH("PRSRSH87S19H501S",'Agosto 2026'!B4:B37,0)),0)+IFERROR(INDEX('Settembre 2026'!AH4:AH37,MATCH("PRSRSH87S19H501S",'Settembre 2026'!B4:B37,0)),0) | K22: =IFERROR(INDEX('Aprile 2026'!AJ4:AJ37,MATCH("PRSRSH87S19H501S",'Aprile 2026'!B4:B37,0)),0)+IFERROR(INDEX('Maggio 2026'!AK4:AK37,MATCH("PRSRSH87S19H501S",'Maggio 2026'!B4:B37,0)),0)+IFERROR(INDEX('Giugno 2026'!AJ4:AJ37,MATCH("PRSRSH87S19H501S",'Giugno 2026'!B4:B37,0)),0)+IFERROR(INDEX('Luglio 2026'!AK4:AK37,MATCH("PRSRSH87S19H501S",'Luglio 2026'!B4:B37,0)),0)+IFERROR(INDEX('Agosto 2026'!AK4:AK37,MATCH("PRSRSH87S19H501S",'Agosto 2026'!B4:B37,0)),0)+IFERROR(INDEX('Settembre 2026'!AJ4:AJ37,MATCH("PRSRSH87S19H501S",'Settembre 2026'!B4:B37,0)),0) | L22: =IF(75=0,0,MIN((J22*24)/150,1)) | M22: La Cyber Security; Cloud e Fog Computing | N22: 12.412671 | O22: 6.1861767 | P22: =(N22+O22)*J22*24
A23: PUDDU RAIMONDO | B23: PDDRND75R08H501S | C23: Big Data - Tecninf - Fondoconoscenza | J23: =IFERROR(INDEX('Aprile 2026'!AH4:AH37,MATCH("PDDRND75R08H501S",'Aprile 2026'!B4:B37,0)),0)+IFERROR(INDEX('Maggio 2026'!AI4:AI37,MATCH("PDDRND75R08H501S",'Maggio 2026'!B4:B37,0)),0)+IFERROR(INDEX('Giugno 2026'!AH4:AH37,MATCH("PDDRND75R08H501S",'Giugno 2026'!B4:B37,0)),0)+IFERROR(INDEX('Luglio 2026'!AI4:AI37,MATCH("PDDRND75R08H501S",'Luglio 2026'!B4:B37,0)),0)+IFERROR(INDEX('Agosto 2026'!AI4:AI37,MATCH("PDDRND75R08H501S",'Agosto 2026'!B4:B37,0)),0)+IFERROR(INDEX('Settembre 2026'!AH4:AH37,MATCH("PDDRND75R08H501S",'Settembre 2026'!B4:B37,0)),0) | K23: =IFERROR(INDEX('Aprile 2026'!AJ4:AJ37,MATCH("PDDRND75R08H501S",'Aprile 2026'!B4:B37,0)),0)+IFERROR(INDEX('Maggio 2026'!AK4:AK37,MATCH("PDDRND75R08H501S",'Maggio 2026'!B4:B37,0)),0)+IFERROR(INDEX('Giugno 2026'!AJ4:AJ37,MATCH("PDDRND75R08H501S",'Giugno 2026'!B4:B37,0)),0)+IFERROR(INDEX('Luglio 2026'!AK4:AK37,MATCH("PDDRND75R08H501S",'Luglio 2026'!B4:B37,0)),0)+IFERROR(INDEX('Agosto 2026'!AK4:AK37,MATCH("PDDRND75R08H501S",'Agosto 2026'!B4:B37,0)),0)+IFERROR(INDEX('Settembre 2026'!AJ4:AJ37,MATCH("PDDRND75R08H501S",'Settembre 2026'!B4:B37,0)),0) | L23: =IF(75=0,0,MIN((J23*24)/150,1)) | M23: Big data e analisi predittiva; Deep Learning e reti neurali | N23: 11.02898 | O23: 5.4965821 | P23: =(N23+O23)*J23*24
A24: RANIERI FRANCESCO | B24: RNRFNC99L28H501B | C24: La programmazione - Tecninf - Fondoconoscenza | J24: =IFERROR(INDEX('Aprile 2026'!AH4:AH37,MATCH("RNRFNC99L28H501B",'Aprile 2026'!B4:B37,0)),0)+IFERROR(INDEX('Maggio 2026'!AI4:AI37,MATCH("RNRFNC99L28H501B",'Maggio 2026'!B4:B37,0)),0)+IFERROR(INDEX('Giugno 2026'!AH4:AH37,MATCH("RNRFNC99L28H501B",'Giugno 2026'!B4:B37,0)),0)+IFERROR(INDEX('Luglio 2026'!AI4:AI37,MATCH("RNRFNC99L28H501B",'Luglio 2026'!B4:B37,0)),0)+IFERROR(INDEX('Agosto 2026'!AI4:AI37,MATCH("RNRFNC99L28H501B",'Agosto 2026'!B4:B37,0)),0)+IFERROR(INDEX('Settembre 2026'!AH4:AH37,MATCH("RNRFNC99L28H501B",'Settembre 2026'!B4:B37,0)),0) | K24: =IFERROR(INDEX('Aprile 2026'!AJ4:AJ37,MATCH("RNRFNC99L28H501B",'Aprile 2026'!B4:B37,0)),0)+IFERROR(INDEX('Maggio 2026'!AK4:AK37,MATCH("RNRFNC99L28H501B",'Maggio 2026'!B4:B37,0)),0)+IFERROR(INDEX('Giugno 2026'!AJ4:AJ37,MATCH("RNRFNC99L28H501B",'Giugno 2026'!B4:B37,0)),0)+IFERROR(INDEX('Luglio 2026'!AK4:AK37,MATCH("RNRFNC99L28H501B",'Luglio 2026'!B4:B37,0)),0)+IFERROR(INDEX('Agosto 2026'!AK4:AK37,MATCH("RNRFNC99L28H501B",'Agosto 2026'!B4:B37,0)),0)+IFERROR(INDEX('Settembre 2026'!AJ4:AJ37,MATCH("RNRFNC99L28H501B",'Settembre 2026'!B4:B37,0)),0) | L24: =IF(75=0,0,MIN((J24*24)/150,1)) | M24: GDPR e nuove normative Europee; I sistemi operativi; Linguaggi di programmazione; Front end base: HTML, CSS, Bootstrap; Back end base: Fondamenti di PHP; Applicazioni dinamiche con PHP e MySql | N24: 9.8581647 | O24: 1.6745114 | P24: =(N24+O24)*J24*24
A25: ROSA JEREMY DELA | B25: DLRJMY02A20H501A | C25: Big Data - Tecninf - Fondoconoscenza | J25: =IFERROR(INDEX('Aprile 2026'!AH4:AH37,MATCH("DLRJMY02A20H501A",'Aprile 2026'!B4:B37,0)),0)+IFERROR(INDEX('Maggio 2026'!AI4:AI37,MATCH("DLRJMY02A20H501A",'Maggio 2026'!B4:B37,0)),0)+IFERROR(INDEX('Giugno 2026'!AH4:AH37,MATCH("DLRJMY02A20H501A",'Giugno 2026'!B4:B37,0)),0)+IFERROR(INDEX('Luglio 2026'!AI4:AI37,MATCH("DLRJMY02A20H501A",'Luglio 2026'!B4:B37,0)),0)+IFERROR(INDEX('Agosto 2026'!AI4:AI37,MATCH("DLRJMY02A20H501A",'Agosto 2026'!B4:B37,0)),0)+IFERROR(INDEX('Settembre 2026'!AH4:AH37,MATCH("DLRJMY02A20H501A",'Settembre 2026'!B4:B37,0)),0) | K25: =IFERROR(INDEX('Aprile 2026'!AJ4:AJ37,MATCH("DLRJMY02A20H501A",'Aprile 2026'!B4:B37,0)),0)+IFERROR(INDEX('Maggio 2026'!AK4:AK37,MATCH("DLRJMY02A20H501A",'Maggio 2026'!B4:B37,0)),0)+IFERROR(INDEX('Giugno 2026'!AJ4:AJ37,MATCH("DLRJMY02A20H501A",'Giugno 2026'!B4:B37,0)),0)+IFERROR(INDEX('Luglio 2026'!AK4:AK37,MATCH("DLRJMY02A20H501A",'Luglio 2026'!B4:B37,0)),0)+IFERROR(INDEX('Agosto 2026'!AK4:AK37,MATCH("DLRJMY02A20H501A",'Agosto 2026'!B4:B37,0)),0)+IFERROR(INDEX('Settembre 2026'!AJ4:AJ37,MATCH("DLRJMY02A20H501A",'Settembre 2026'!B4:B37,0)),0) | L25: =IF(75=0,0,MIN((J25*24)/150,1)) | M25: Nessuno - i corsi iniziati sono al 100% | N25: 8.7460465 | O25: 2.0936329 | P25: =(N25+O25)*J25*24
A26: SALPIETRO GIANLUCA | B26: SLPGLC81B17G377J | C26: Big Data - Tecninf - Fondoconoscenza | J26: =IFERROR(INDEX('Aprile 2026'!AH4:AH37,MATCH("SLPGLC81B17G377J",'Aprile 2026'!B4:B37,0)),0)+IFERROR(INDEX('Maggio 2026'!AI4:AI37,MATCH("SLPGLC81B17G377J",'Maggio 2026'!B4:B37,0)),0)+IFERROR(INDEX('Giugno 2026'!AH4:AH37,MATCH("SLPGLC81B17G377J",'Giugno 2026'!B4:B37,0)),0)+IFERROR(INDEX('Luglio 2026'!AI4:AI37,MATCH("SLPGLC81B17G377J",'Luglio 2026'!B4:B37,0)),0)+IFERROR(INDEX('Agosto 2026'!AI4:AI37,MATCH("SLPGLC81B17G377J",'Agosto 2026'!B4:B37,0)),0)+IFERROR(INDEX('Settembre 2026'!AH4:AH37,MATCH("SLPGLC81B17G377J",'Settembre 2026'!B4:B37,0)),0) | K26: =IFERROR(INDEX('Aprile 2026'!AJ4:AJ37,MATCH("SLPGLC81B17G377J",'Aprile 2026'!B4:B37,0)),0)+IFERROR(INDEX('Maggio 2026'!AK4:AK37,MATCH("SLPGLC81B17G377J",'Maggio 2026'!B4:B37,0)),0)+IFERROR(INDEX('Giugno 2026'!AJ4:AJ37,MATCH("SLPGLC81B17G377J",'Giugno 2026'!B4:B37,0)),0)+IFERROR(INDEX('Luglio 2026'!AK4:AK37,MATCH("SLPGLC81B17G377J",'Luglio 2026'!B4:B37,0)),0)+IFERROR(INDEX('Agosto 2026'!AK4:AK37,MATCH("SLPGLC81B17G377J",'Agosto 2026'!B4:B37,0)),0)+IFERROR(INDEX('Settembre 2026'!AJ4:AJ37,MATCH("SLPGLC81B17G377J",'Settembre 2026'!B4:B37,0)),0) | L26: =IF(75=0,0,MIN((J26*24)/150,1)) | M26: Big data e analisi predittiva; I Big data in ambito finanziario; Gestione avanzata di un Database; Sicurezza e Password Management | N26: 9.731453 | O26: 4.8499263 | P26: =(N26+O26)*J26*24
A27: SALVATI CARMINE | B27: SLVCMN80D14D086Z | C27: Big Data - Tecninf - Fondoconoscenza | J27: =IFERROR(INDEX('Aprile 2026'!AH4:AH37,MATCH("SLVCMN80D14D086Z",'Aprile 2026'!B4:B37,0)),0)+IFERROR(INDEX('Maggio 2026'!AI4:AI37,MATCH("SLVCMN80D14D086Z",'Maggio 2026'!B4:B37,0)),0)+IFERROR(INDEX('Giugno 2026'!AH4:AH37,MATCH("SLVCMN80D14D086Z",'Giugno 2026'!B4:B37,0)),0)+IFERROR(INDEX('Luglio 2026'!AI4:AI37,MATCH("SLVCMN80D14D086Z",'Luglio 2026'!B4:B37,0)),0)+IFERROR(INDEX('Agosto 2026'!AI4:AI37,MATCH("SLVCMN80D14D086Z",'Agosto 2026'!B4:B37,0)),0)+IFERROR(INDEX('Settembre 2026'!AH4:AH37,MATCH("SLVCMN80D14D086Z",'Settembre 2026'!B4:B37,0)),0) | K27: =IFERROR(INDEX('Aprile 2026'!AJ4:AJ37,MATCH("SLVCMN80D14D086Z",'Aprile 2026'!B4:B37,0)),0)+IFERROR(INDEX('Maggio 2026'!AK4:AK37,MATCH("SLVCMN80D14D086Z",'Maggio 2026'!B4:B37,0)),0)+IFERROR(INDEX('Giugno 2026'!AJ4:AJ37,MATCH("SLVCMN80D14D086Z",'Giugno 2026'!B4:B37,0)),0)+IFERROR(INDEX('Luglio 2026'!AK4:AK37,MATCH("SLVCMN80D14D086Z",'Luglio 2026'!B4:B37,0)),0)+IFERROR(INDEX('Agosto 2026'!AK4:AK37,MATCH("SLVCMN80D14D086Z",'Agosto 2026'!B4:B37,0)),0)+IFERROR(INDEX('Settembre 2026'!AJ4:AJ37,MATCH("SLVCMN80D14D086Z",'Settembre 2026'!B4:B37,0)),0) | L27: =IF(75=0,0,MIN((J27*24)/150,1)) | M27: GDPR e nuove normative Europee; Big data e analisi predittiva; I Big data in ambito finanziario; Database relazionali e linguaggio SQL con PHP; Natural Language Processing con Python; Il Machine Learning con Python; Progettare autorizzazioni e autentificazioni; Gestione avanzata di un Database; Sicurezza e Password Management | N27: 11.662538 | O27: 5.8123056 | P27: =(N27+O27)*J27*24
A28: SAMBRINI ALESSIA | B28: SMBLSS74D47H501E | C28: Big Data - Tecninf - Fondoconoscenza | J28: =IFERROR(INDEX('Aprile 2026'!AH4:AH37,MATCH("SMBLSS74D47H501E",'Aprile 2026'!B4:B37,0)),0)+IFERROR(INDEX('Maggio 2026'!AI4:AI37,MATCH("SMBLSS74D47H501E",'Maggio 2026'!B4:B37,0)),0)+IFERROR(INDEX('Giugno 2026'!AH4:AH37,MATCH("SMBLSS74D47H501E",'Giugno 2026'!B4:B37,0)),0)+IFERROR(INDEX('Luglio 2026'!AI4:AI37,MATCH("SMBLSS74D47H501E",'Luglio 2026'!B4:B37,0)),0)+IFERROR(INDEX('Agosto 2026'!AI4:AI37,MATCH("SMBLSS74D47H501E",'Agosto 2026'!B4:B37,0)),0)+IFERROR(INDEX('Settembre 2026'!AH4:AH37,MATCH("SMBLSS74D47H501E",'Settembre 2026'!B4:B37,0)),0) | K28: =IFERROR(INDEX('Aprile 2026'!AJ4:AJ37,MATCH("SMBLSS74D47H501E",'Aprile 2026'!B4:B37,0)),0)+IFERROR(INDEX('Maggio 2026'!AK4:AK37,MATCH("SMBLSS74D47H501E",'Maggio 2026'!B4:B37,0)),0)+IFERROR(INDEX('Giugno 2026'!AJ4:AJ37,MATCH("SMBLSS74D47H501E",'Giugno 2026'!B4:B37,0)),0)+IFERROR(INDEX('Luglio 2026'!AK4:AK37,MATCH("SMBLSS74D47H501E",'Luglio 2026'!B4:B37,0)),0)+IFERROR(INDEX('Agosto 2026'!AK4:AK37,MATCH("SMBLSS74D47H501E",'Agosto 2026'!B4:B37,0)),0)+IFERROR(INDEX('Settembre 2026'!AJ4:AJ37,MATCH("SMBLSS74D47H501E",'Settembre 2026'!B4:B37,0)),0) | L28: =IF(75=0,0,MIN((J28*24)/150,1)) | M28: Introduzione ai Big Data nelle aziende; Big data e analisi predittiva; Progettare autorizzazioni e autentificazioni | N28: 10.425833 | O28: 5.1310045 | P28: =(N28+O28)*J28*24
A29: SAVAIANO SILVIA | B29: SVNSLV89A46H501I | C29: La programmazione - Tecninf - Fondoconoscenza | J29: =IFERROR(INDEX('Aprile 2026'!AH4:AH37,MATCH("SVNSLV89A46H501I",'Aprile 2026'!B4:B37,0)),0)+IFERROR(INDEX('Maggio 2026'!AI4:AI37,MATCH("SVNSLV89A46H501I",'Maggio 2026'!B4:B37,0)),0)+IFERROR(INDEX('Giugno 2026'!AH4:AH37,MATCH("SVNSLV89A46H501I",'Giugno 2026'!B4:B37,0)),0)+IFERROR(INDEX('Luglio 2026'!AI4:AI37,MATCH("SVNSLV89A46H501I",'Luglio 2026'!B4:B37,0)),0)+IFERROR(INDEX('Agosto 2026'!AI4:AI37,MATCH("SVNSLV89A46H501I",'Agosto 2026'!B4:B37,0)),0)+IFERROR(INDEX('Settembre 2026'!AH4:AH37,MATCH("SVNSLV89A46H501I",'Settembre 2026'!B4:B37,0)),0) | K29: =IFERROR(INDEX('Aprile 2026'!AJ4:AJ37,MATCH("SVNSLV89A46H501I",'Aprile 2026'!B4:B37,0)),0)+IFERROR(INDEX('Maggio 2026'!AK4:AK37,MATCH("SVNSLV89A46H501I",'Maggio 2026'!B4:B37,0)),0)+IFERROR(INDEX('Giugno 2026'!AJ4:AJ37,MATCH("SVNSLV89A46H501I",'Giugno 2026'!B4:B37,0)),0)+IFERROR(INDEX('Luglio 2026'!AK4:AK37,MATCH("SVNSLV89A46H501I",'Luglio 2026'!B4:B37,0)),0)+IFERROR(INDEX('Agosto 2026'!AK4:AK37,MATCH("SVNSLV89A46H501I",'Agosto 2026'!B4:B37,0)),0)+IFERROR(INDEX('Settembre 2026'!AJ4:AJ37,MATCH("SVNSLV89A46H501I",'Settembre 2026'!B4:B37,0)),0) | L29: =IF(75=0,0,MIN((J29*24)/150,1)) | M29: GDPR e nuove normative Europee; I sistemi operativi; Linguaggi di programmazione; Back end base: Fondamenti di PHP | N29: 9.731453 | O29: 4.8499263 | P29: =(N29+O29)*J29*24
A30: SCALVEDI FILIPPO | B30: SCLFPP97S05H501K | C30: Big Data - Tecninf - Fondoconoscenza | J30: =IFERROR(INDEX('Aprile 2026'!AH4:AH37,MATCH("SCLFPP97S05H501K",'Aprile 2026'!B4:B37,0)),0)+IFERROR(INDEX('Maggio 2026'!AI4:AI37,MATCH("SCLFPP97S05H501K",'Maggio 2026'!B4:B37,0)),0)+IFERROR(INDEX('Giugno 2026'!AH4:AH37,MATCH("SCLFPP97S05H501K",'Giugno 2026'!B4:B37,0)),0)+IFERROR(INDEX('Luglio 2026'!AI4:AI37,MATCH("SCLFPP97S05H501K",'Luglio 2026'!B4:B37,0)),0)+IFERROR(INDEX('Agosto 2026'!AI4:AI37,MATCH("SCLFPP97S05H501K",'Agosto 2026'!B4:B37,0)),0)+IFERROR(INDEX('Settembre 2026'!AH4:AH37,MATCH("SCLFPP97S05H501K",'Settembre 2026'!B4:B37,0)),0) | K30: =IFERROR(INDEX('Aprile 2026'!AJ4:AJ37,MATCH("SCLFPP97S05H501K",'Aprile 2026'!B4:B37,0)),0)+IFERROR(INDEX('Maggio 2026'!AK4:AK37,MATCH("SCLFPP97S05H501K",'Maggio 2026'!B4:B37,0)),0)+IFERROR(INDEX('Giugno 2026'!AJ4:AJ37,MATCH("SCLFPP97S05H501K",'Giugno 2026'!B4:B37,0)),0)+IFERROR(INDEX('Luglio 2026'!AK4:AK37,MATCH("SCLFPP97S05H501K",'Luglio 2026'!B4:B37,0)),0)+IFERROR(INDEX('Agosto 2026'!AK4:AK37,MATCH("SCLFPP97S05H501K",'Agosto 2026'!B4:B37,0)),0)+IFERROR(INDEX('Settembre 2026'!AJ4:AJ37,MATCH("SCLFPP97S05H501K",'Settembre 2026'!B4:B37,0)),0) | L30: =IF(75=0,0,MIN((J30*24)/150,1)) | M30: Big Data Analytics con Python e Spark | N30: 9.8581647 | O30: 1.6837575 | P30: =(N30+O30)*J30*24
A31: SCRIMIERI TIZIANO | B31: SCRTZN80A09H501I | C31: Big Data - Tecninf - Fondoconoscenza | J31: =IFERROR(INDEX('Aprile 2026'!AH4:AH37,MATCH("SCRTZN80A09H501I",'Aprile 2026'!B4:B37,0)),0)+IFERROR(INDEX('Maggio 2026'!AI4:AI37,MATCH("SCRTZN80A09H501I",'Maggio 2026'!B4:B37,0)),0)+IFERROR(INDEX('Giugno 2026'!AH4:AH37,MATCH("SCRTZN80A09H501I",'Giugno 2026'!B4:B37,0)),0)+IFERROR(INDEX('Luglio 2026'!AI4:AI37,MATCH("SCRTZN80A09H501I",'Luglio 2026'!B4:B37,0)),0)+IFERROR(INDEX('Agosto 2026'!AI4:AI37,MATCH("SCRTZN80A09H501I",'Agosto 2026'!B4:B37,0)),0)+IFERROR(INDEX('Settembre 2026'!AH4:AH37,MATCH("SCRTZN80A09H501I",'Settembre 2026'!B4:B37,0)),0) | K31: =IFERROR(INDEX('Aprile 2026'!AJ4:AJ37,MATCH("SCRTZN80A09H501I",'Aprile 2026'!B4:B37,0)),0)+IFERROR(INDEX('Maggio 2026'!AK4:AK37,MATCH("SCRTZN80A09H501I",'Maggio 2026'!B4:B37,0)),0)+IFERROR(INDEX('Giugno 2026'!AJ4:AJ37,MATCH("SCRTZN80A09H501I",'Giugno 2026'!B4:B37,0)),0)+IFERROR(INDEX('Luglio 2026'!AK4:AK37,MATCH("SCRTZN80A09H501I",'Luglio 2026'!B4:B37,0)),0)+IFERROR(INDEX('Agosto 2026'!AK4:AK37,MATCH("SCRTZN80A09H501I",'Agosto 2026'!B4:B37,0)),0)+IFERROR(INDEX('Settembre 2026'!AJ4:AJ37,MATCH("SCRTZN80A09H501I",'Settembre 2026'!B4:B37,0)),0) | L31: =IF(75=0,0,MIN((J31*24)/150,1)) | M31: GDPR e nuove normative Europee; Big data e analisi predittiva; Database relazionali e linguaggio SQL con PHP; Deep Learning e reti neurali | N31: 12.240343 | O31: 6.0163062 | P31: =(N31+O31)*J31*24
A32: STASIUC DENIS | B32: STSDNS91B05Z140T | C32: Big Data - Tecninf - Fondoconoscenza | J32: =IFERROR(INDEX('Aprile 2026'!AH4:AH37,MATCH("STSDNS91B05Z140T",'Aprile 2026'!B4:B37,0)),0)+IFERROR(INDEX('Maggio 2026'!AI4:AI37,MATCH("STSDNS91B05Z140T",'Maggio 2026'!B4:B37,0)),0)+IFERROR(INDEX('Giugno 2026'!AH4:AH37,MATCH("STSDNS91B05Z140T",'Giugno 2026'!B4:B37,0)),0)+IFERROR(INDEX('Luglio 2026'!AI4:AI37,MATCH("STSDNS91B05Z140T",'Luglio 2026'!B4:B37,0)),0)+IFERROR(INDEX('Agosto 2026'!AI4:AI37,MATCH("STSDNS91B05Z140T",'Agosto 2026'!B4:B37,0)),0)+IFERROR(INDEX('Settembre 2026'!AH4:AH37,MATCH("STSDNS91B05Z140T",'Settembre 2026'!B4:B37,0)),0) | K32: =IFERROR(INDEX('Aprile 2026'!AJ4:AJ37,MATCH("STSDNS91B05Z140T",'Aprile 2026'!B4:B37,0)),0)+IFERROR(INDEX('Maggio 2026'!AK4:AK37,MATCH("STSDNS91B05Z140T",'Maggio 2026'!B4:B37,0)),0)+IFERROR(INDEX('Giugno 2026'!AJ4:AJ37,MATCH("STSDNS91B05Z140T",'Giugno 2026'!B4:B37,0)),0)+IFERROR(INDEX('Luglio 2026'!AK4:AK37,MATCH("STSDNS91B05Z140T",'Luglio 2026'!B4:B37,0)),0)+IFERROR(INDEX('Agosto 2026'!AK4:AK37,MATCH("STSDNS91B05Z140T",'Agosto 2026'!B4:B37,0)),0)+IFERROR(INDEX('Settembre 2026'!AJ4:AJ37,MATCH("STSDNS91B05Z140T",'Settembre 2026'!B4:B37,0)),0) | L32: =IF(75=0,0,MIN((J32*24)/150,1)) | M32: I Big data in ambito finanziario; Natural Language Processing con Python | N32: 10.288984 | O32: 5.1277614 | P32: =(N32+O32)*J32*24
A33: TARISCIOTTI ANDREA | B33: TRSNDR97M24H501B | C33: La programmazione - Tecninf - Fondoconoscenza | J33: =IFERROR(INDEX('Aprile 2026'!AH4:AH37,MATCH("TRSNDR97M24H501B",'Aprile 2026'!B4:B37,0)),0)+IFERROR(INDEX('Maggio 2026'!AI4:AI37,MATCH("TRSNDR97M24H501B",'Maggio 2026'!B4:B37,0)),0)+IFERROR(INDEX('Giugno 2026'!AH4:AH37,MATCH("TRSNDR97M24H501B",'Giugno 2026'!B4:B37,0)),0)+IFERROR(INDEX('Luglio 2026'!AI4:AI37,MATCH("TRSNDR97M24H501B",'Luglio 2026'!B4:B37,0)),0)+IFERROR(INDEX('Agosto 2026'!AI4:AI37,MATCH("TRSNDR97M24H501B",'Agosto 2026'!B4:B37,0)),0)+IFERROR(INDEX('Settembre 2026'!AH4:AH37,MATCH("TRSNDR97M24H501B",'Settembre 2026'!B4:B37,0)),0) | K33: =IFERROR(INDEX('Aprile 2026'!AJ4:AJ37,MATCH("TRSNDR97M24H501B",'Aprile 2026'!B4:B37,0)),0)+IFERROR(INDEX('Maggio 2026'!AK4:AK37,MATCH("TRSNDR97M24H501B",'Maggio 2026'!B4:B37,0)),0)+IFERROR(INDEX('Giugno 2026'!AJ4:AJ37,MATCH("TRSNDR97M24H501B",'Giugno 2026'!B4:B37,0)),0)+IFERROR(INDEX('Luglio 2026'!AK4:AK37,MATCH("TRSNDR97M24H501B",'Luglio 2026'!B4:B37,0)),0)+IFERROR(INDEX('Agosto 2026'!AK4:AK37,MATCH("TRSNDR97M24H501B",'Agosto 2026'!B4:B37,0)),0)+IFERROR(INDEX('Settembre 2026'!AJ4:AJ37,MATCH("TRSNDR97M24H501B",'Settembre 2026'!B4:B37,0)),0) | L33: =IF(75=0,0,MIN((J33*24)/150,1)) | M33: Front end avanzato: JavaScript e jQuery; Applicazioni dinamiche con PHP e MySql | N33: 10.527202 | O33: 5.7773853 | P33: =(N33+O33)*J33*24
A34: TOCI ANTONETA | B34: TCONNT91H59Z100O | C34: La programmazione - Tecninf - Fondoconoscenza | J34: =IFERROR(INDEX('Aprile 2026'!AH4:AH37,MATCH("TCONNT91H59Z100O",'Aprile 2026'!B4:B37,0)),0)+IFERROR(INDEX('Maggio 2026'!AI4:AI37,MATCH("TCONNT91H59Z100O",'Maggio 2026'!B4:B37,0)),0)+IFERROR(INDEX('Giugno 2026'!AH4:AH37,MATCH("TCONNT91H59Z100O",'Giugno 2026'!B4:B37,0)),0)+IFERROR(INDEX('Luglio 2026'!AI4:AI37,MATCH("TCONNT91H59Z100O",'Luglio 2026'!B4:B37,0)),0)+IFERROR(INDEX('Agosto 2026'!AI4:AI37,MATCH("TCONNT91H59Z100O",'Agosto 2026'!B4:B37,0)),0)+IFERROR(INDEX('Settembre 2026'!AH4:AH37,MATCH("TCONNT91H59Z100O",'Settembre 2026'!B4:B37,0)),0) | K34: =IFERROR(INDEX('Aprile 2026'!AJ4:AJ37,MATCH("TCONNT91H59Z100O",'Aprile 2026'!B4:B37,0)),0)+IFERROR(INDEX('Maggio 2026'!AK4:AK37,MATCH("TCONNT91H59Z100O",'Maggio 2026'!B4:B37,0)),0)+IFERROR(INDEX('Giugno 2026'!AJ4:AJ37,MATCH("TCONNT91H59Z100O",'Giugno 2026'!B4:B37,0)),0)+IFERROR(INDEX('Luglio 2026'!AK4:AK37,MATCH("TCONNT91H59Z100O",'Luglio 2026'!B4:B37,0)),0)+IFERROR(INDEX('Agosto 2026'!AK4:AK37,MATCH("TCONNT91H59Z100O",'Agosto 2026'!B4:B37,0)),0)+IFERROR(INDEX('Settembre 2026'!AJ4:AJ37,MATCH("TCONNT91H59Z100O",'Settembre 2026'!B4:B37,0)),0) | L34: =IF(75=0,0,MIN((J34*24)/150,1)) | M34: Nessuno - i corsi iniziati sono al 100% | N34: 9.731453 | O34: 4.8499263 | P34: =(N34+O34)*J34*24
A35: VISWANATHAN SRIDHAR | B35: VSWSDH86S22Z222H | C35: Project Management per il digitale - Tecninf - Fondoconoscenza | J35: =IFERROR(INDEX('Aprile 2026'!AH4:AH37,MATCH("VSWSDH86S22Z222H",'Aprile 2026'!B4:B37,0)),0)+IFERROR(INDEX('Maggio 2026'!AI4:AI37,MATCH("VSWSDH86S22Z222H",'Maggio 2026'!B4:B37,0)),0)+IFERROR(INDEX('Giugno 2026'!AH4:AH37,MATCH("VSWSDH86S22Z222H",'Giugno 2026'!B4:B37,0)),0)+IFERROR(INDEX('Luglio 2026'!AI4:AI37,MATCH("VSWSDH86S22Z222H",'Luglio 2026'!B4:B37,0)),0)+IFERROR(INDEX('Agosto 2026'!AI4:AI37,MATCH("VSWSDH86S22Z222H",'Agosto 2026'!B4:B37,0)),0)+IFERROR(INDEX('Settembre 2026'!AH4:AH37,MATCH("VSWSDH86S22Z222H",'Settembre 2026'!B4:B37,0)),0) | K35: =IFERROR(INDEX('Aprile 2026'!AJ4:AJ37,MATCH("VSWSDH86S22Z222H",'Aprile 2026'!B4:B37,0)),0)+IFERROR(INDEX('Maggio 2026'!AK4:AK37,MATCH("VSWSDH86S22Z222H",'Maggio 2026'!B4:B37,0)),0)+IFERROR(INDEX('Giugno 2026'!AJ4:AJ37,MATCH("VSWSDH86S22Z222H",'Giugno 2026'!B4:B37,0)),0)+IFERROR(INDEX('Luglio 2026'!AK4:AK37,MATCH("VSWSDH86S22Z222H",'Luglio 2026'!B4:B37,0)),0)+IFERROR(INDEX('Agosto 2026'!AK4:AK37,MATCH("VSWSDH86S22Z222H",'Agosto 2026'!B4:B37,0)),0)+IFERROR(INDEX('Settembre 2026'!AJ4:AJ37,MATCH("VSWSDH86S22Z222H",'Settembre 2026'!B4:B37,0)),0) | L35: =IF(75=0,0,MIN((J35*24)/150,1)) | M35: Influenzare positivamente il clima aziendale | N35: 11.991988 | O35: 5.9764755 | P35: =(N35+O35)*J35*24
A36: TOTALE | J36: =SUM(J3:J35) | K36: =SUM(K3:K35) | P36: =SUM(P3:P35)
A37: TOTALE NON FINANZIATO

Sheet Aprile 2026
A1: MONITORAGGIO ORE FORMAZIONE - Aprile 2026 - TECNINF SPA
A3: Utente | B3: Codice Fiscale | C3: Percorso Formativo | D3: 1 M | E3: 2 G | F3: 3 V | G3: 4 S | H3: 5 D | I3: 6 L | J3: 7 M | K3: 8 M | L3: 9 G | M3: 10 V | N3: 11 S | O3: 12 D | P3: 13 L | Q3: 14 M | R3: 15 M | S3: 16 G | T3: 17 V | U3: 18 S | V3: 19 D | W3: 20 L | X3: 21 M | Y3: 22 M | Z3: 23 G | AA3: 24 V | AB3: 25 S | AC3: 26 D | AD3: 27 L | AE3: 28 M | AF3: 29 M | AG3: 30 G | AH3: Totale Ore Effettive | AI3: Ore Totali | AJ3: Totale Eccesso | AK3: Eccesso Weekend | AL3: Eccesso Dopo 18:00 | AM3: Eccesso Mattutino
A4: ALBA WILLIAM JULIAN PAZ | B4: PZLWLM96A16Z504F | C4: La programmazione - Tecninf - Fondoconoscenza | AG4: 0.029780093 | AH4: =SUM(D4:AG4) | AI4: 0.029780093 | AJ4: =AI4-AH4
A5: BADII ALESSANDRO | B5: BDALSN01R03H501Z | C5: Big Data - Tecninf - Fondoconoscenza | AH5: =SUM(D5:AG5) | AJ5: =AI5-AH5
A6: BADINE HICHAM | B6: BDNHHM97H19H501Q | C6: La programmazione - Tecninf - Fondoconoscenza | AH6: =SUM(D6:AG6) | AJ6: =AI6-AH6
A7: BECIANI ANDREA | B7: BCNNDR82P16D773D | C7: La programmazione - Tecninf - Fondoconoscenza | AF7: 0.12271991 | AG7: 0.099780093 | AH7: =SUM(D7:AG7) | AI7: 0.2474537 | AJ7: =AI7-AH7 | AL7: 0.024953704
A8: BOONTAWEE JUTATIP | B8: BNTJTP78S54Z241U | C8: Project Management per il digitale - Tecninf - Fondoconoscenza | AH8: =SUM(D8:AG8) | AJ8: =AI8-AH8
A9: BUTTINELLI GIORGIA | B9: BTTGRG97S59G274Q | C9: Big Data - Tecninf - Fondoconoscenza | AH9: =SUM(D9:AG9) | AJ9: =AI9-AH9
A10: CARABLUT VICTOR | B10: CRBVTR94A11Z140B | C10: Sicurezza Informatica - Tecninf - Fondoconoscenza | AH10: =SUM(D10:AG10) | AJ10: =AI10-AH10
A11: CECCONI ANTHONY | B11: CCCNHN91D19H501W | C11: La programmazione - Tecninf - Fondoconoscenza | AE11: 0.15533565 | AF11: 0.13935185 | AH11: =SUM(D11:AG11) | AI11: 0.2946875 | AJ11: =AI11-AH11
A12: CHIARA GOBBI MARIA | B12: GBBMCH73R57H501G | C12: L'ufficio digitale - Tecninf - Fondoconoscenza | AH12: =SUM(D12:AG12) | AJ12: =AI12-AH12
A13: LIMETTI ION | B13: LMTNIO94M03Z129S | C13: Big Data - Tecninf - Fondoconoscenza | AH13: =SUM(D13:AG13) | AJ13: =AI13-AH13
A14: LUCA' VERONICA | B14: LCUVNC85L52D976T | C14: Big Data - Tecninf - Fondoconoscenza | AE14: 0.045289352 | AH14: =SUM(D14:AG14) | AI14: 0.045289352 | AJ14: =AI14-AH14
A15: MAGNANINI LORENZO | B15: MGNLNZ97M04H501T | C15: La programmazione - Tecninf - Fondoconoscenza | AH15: =SUM(D15:AG15) | AJ15: =AI15-AH15
A16: MARIANI ALESSIA | B16: MRNLSS75L68H501L | C16: Big Data - Tecninf - Fondoconoscenza | AH16: =SUM(D16:AG16) | AJ16: =AI16-AH16
A17: MASCELLINO GIULIO | B17: MSCGLI83C04G511L | C17: Big Data - Tecninf - Fondoconoscenza | AH17: =SUM(D17:AG17) | AJ17: =AI17-AH17
A18: PACPACO MICHAEL DEPOLLY | B18: PCPMHL00R03H501G | C18: La programmazione - Tecninf - Fondoconoscenza | AE18: 0.081643519 | AF18: 0.026493056 | AH18: =SUM(D18:AG18) | AI18: 0.10813657 | AJ18: =AI18-AH18
A19: PASSIO ROBERTA | B19: PSSRRT76L56H501O | C19: Sicurezza Informatica - Tecninf - Fondoconoscenza | AH19: =SUM(D19:AG19) | AJ19: =AI19-AH19
A20: PERILLA GIAN LEO GAMES | B20: PRLGLG98M18H501X | C20: Big Data - Tecninf - Fondoconoscenza | AH20: =SUM(D20:AG20) | AJ20: =AI20-AH20
A21: PINNA ROBERTO CAO | B21: CPNRRT66D27H501V | C21: Project Management per il digitale - Tecninf - Fondoconoscenza | AH21: =SUM(D21:AG21) | AJ21: =AI21-AH21
A22: POGGI ROBERTO | B22: PGGRRT91H07F839Q | C22: Big Data - Tecninf - Fondoconoscenza | AE22: 0.0068287037 | AH22: =SUM(D22:AG22) | AI22: 0.0068287037 | AJ22: =AI22-AH22
A23: PRASAD RAKESH KUMAR | B23: PRSRSH87S19H501S | C23: Sicurezza Informatica - Tecninf - Fondoconoscenza | AH23: =SUM(D23:AG23) | AJ23: =AI23-AH23
A24: PUDDU RAIMONDO | B24: PDDRND75R08H501S | C24: Big Data - Tecninf - Fondoconoscenza | AG24: 0.00059027778 | AH24: =SUM(D24:AG24) | AI24: 0.00059027778 | AJ24: =AI24-AH24
A25: RANIERI FRANCESCO | B25: RNRFNC99L28H501B | C25: La programmazione - Tecninf - Fondoconoscenza | AH25: =SUM(D25:AG25) | AJ25: =AI25-AH25
A26: ROSA JEREMY DELA | B26: DLRJMY02A20H501A | C26: Big Data - Tecninf - Fondoconoscenza | AH26: =SUM(D26:AG26) | AJ26: =AI26-AH26
A27: SALPIETRO GIANLUCA | B27: SLPGLC81B17G377J | C27: Big Data - Tecninf - Fondoconoscenza | AH27: =SUM(D27:AG27) | AJ27: =AI27-AH27
A28: SALVATI CARMINE | B28: SLVCMN80D14D086Z | C28: Big Data - Tecninf - Fondoconoscenza | AH28: =SUM(D28:AG28) | AJ28: =AI28-AH28
A29: SAMBRINI ALESSIA | B29: SMBLSS74D47H501E | C29: Big Data - Tecninf - Fondoconoscenza | AH29: =SUM(D29:AG29) | AJ29: =AI29-AH29
A30: SAVAIANO SILVIA | B30: SVNSLV89A46H501I | C30: La programmazione - Tecninf - Fondoconoscenza | AH30: =SUM(D30:AG30) | AJ30: =AI30-AH30
A31: SCALVEDI FILIPPO | B31: SCLFPP97S05H501K | C31: Big Data - Tecninf - Fondoconoscenza | AF31: 0.018449074 | AH31: =SUM(D31:AG31) | AI31: 0.018449074 | AJ31: =AI31-AH31
A32: SCRIMIERI TIZIANO | B32: SCRTZN80A09H501I | C32: Big Data - Tecninf - Fondoconoscenza | AH32: =SUM(D32:AG32) | AJ32: =AI32-AH32
A33: STASIUC DENIS | B33: STSDNS91B05Z140T | C33: Big Data - Tecninf - Fondoconoscenza | AE33: 0.023310185 | AG33: 0.012685185 | AH33: =SUM(D33:AG33) | AI33: 0.03599537 | AJ33: =AI33-AH33
A34: TARISCIOTTI ANDREA | B34: TRSNDR97M24H501B | C34: La programmazione - Tecninf - Fondoconoscenza | AE34: 0.00040509259 | AG34: 0 | AH34: =SUM(D34:AG34) | AI34: 0.03275463 | AJ34: =AI34-AH34 | AL34: 0.032349537
A35: TOCI ANTONETA | B35: TCONNT91H59Z100O | C35: La programmazione - Tecninf - Fondoconoscenza | AH35: =SUM(D35:AG35) | AJ35: =AI35-AH35
A36: VISWANATHAN SRIDHAR | B36: VSWSDH86S22Z222H | C36: Project Management per il digitale - Tecninf - Fondoconoscenza | AH36: =SUM(D36:AG36) | AJ36: =AI36-AH36
A37: TOTALE | D37: =SUM(D4:D36) | E37: =SUM(E4:E36) | F37: =SUM(F4:F36) | G37: =SUM(G4:G36) | H37: =SUM(H4:H36) | I37: =SUM(I4:I36) | J37: =SUM(J4:J36) | K37: =SUM(K4:K36) | ... AM37: =SUM(AM4:AM36)

Sheet Maggio 2026
A1: MONITORAGGIO ORE FORMAZIONE - Maggio 2026 - TECNINF SPA
A3: Utente | B3: Codice Fiscale | C3: Percorso Formativo | D3: 1 V | E3: 2 S | F3: 3 D | G3: 4 L | H3: 5 M | I3: 6 M | J3: 7 G | K3: 8 V | L3: 9 S | M3: 10 D | N3: 11 L | O3: 12 M | P3: 13 M | Q3: 14 G | R3: 15 V | S3: 16 S | T3: 17 D | U3: 18 L | V3: 19 M | W3: 20 M | X3: 21 G | Y3: 22 V | Z3: 23 S | AA3: 24 D | AB3: 25 L | AC3: 26 M | AD3: 27 M | AE3: 28 G | AF3: 29 V | AG3: 30 S | AH3: 31 D | AI3: Totale Ore Effettive | AJ3: Ore Totali | AK3: Totale Eccesso | AL3: Eccesso Weekend | AM3: Eccesso Dopo 18:00 | AN3: Eccesso Mattutino
A4: ALBA WILLIAM JULIAN PAZ | B4: PZLWLM96A16Z504F | C4: La programmazione - Tecninf - Fondoconoscenza | G4: 0.0020949074 | K4: 0.0085532407 | O4: 0.021539352 | AI4: =SUM(D4:AH4) | AJ4: 0.0321875 | AK4: =AJ4-AI4
A5: BADII ALESSANDRO | B5: BDALSN01R03H501Z | C5: Big Data - Tecninf - Fondoconoscenza | AI5: =SUM(D5:AH5) | AK5: =AJ5-AI5
A6: BADINE HICHAM | B6: BDNHHM97H19H501Q | C6: La programmazione - Tecninf - Fondoconoscenza | N6: 0.030416667 | O6: 0.025833333 | P6: 0.12313657 | Q6: 0.029490741 | R6: 0.052604167 | U6: 0.034340278 | V6: 0.089178241 | W6: 0.13118056 | X6: 0.12915509 | Y6: 0.15165509 | AB6: 0.13440972 | AC6: 0.12314815 | AD6: 0.0068287037 | AE6: 0.094490741 | AF6: 0.028715278 | AI6: =SUM(D6:AH6) | AJ6: 1.1845833 | AK6: =AJ6-AI6
A7: BECIANI ANDREA | B7: BCNNDR82P16D773D | C7: La programmazione - Tecninf - Fondoconoscenza | G7: 0.016979167 | H7: 0.034560185 | I7: 0.06443287 | J7: 0.0021412037 | K7: 0.035405093 | N7: 0.030243056 | O7: 0.050659722 | R7: 0.026006944 | U7: 0.047650463 | V7: 0.086759259 | W7: 0.18828704 | X7: 0.12716435 | AB7: 0.050729167 | AE7: 0.024189815 | AF7: 0.038981481 | AI7: =SUM(D7:AH7) | AJ7: 0.90327546 | AK7: =AJ7-AI7 | AM7: 0.047523148 | AN7: 0.0315625
A8: BOONTAWEE JUTATIP | B8: BNTJTP78S54Z241U | C8: Project Management per il digitale - Tecninf - Fondoconoscenza | AI8: =SUM(D8:AH8) | AK8: =AJ8-AI8
A9: BUTTINELLI GIORGIA | B9: BTTGRG97S59G274Q | C9: Big Data - Tecninf - Fondoconoscenza | AI9: =SUM(D9:AH9) | AK9: =AJ9-AI9
A10: CARABLUT VICTOR | B10: CRBVTR94A11Z140B | C10: Sicurezza Informatica - Tecninf - Fondoconoscenza | AI10: =SUM(D10:AH10) | AK10: =AJ10-AI10
A11: CECCONI ANTHONY | B11: CCCNHN91D19H501W | C11: La programmazione - Tecninf - Fondoconoscenza | G11: 0.1762037 | H11: 0.089988426 | K11: 0.10079861 | N11: 0.19335648 | O11: 0.10247685 | Q11: 0.22340278 | R11: 0.072337963 | U11: 0.09162037 | V11: 0.075011574 | W11: 0.03900463 | X11: 0.042094907 | AB11: 0.030138889 | AC11: 0.09431713 | AD11: 0.043958333 | AE11: 0.06537037 | AF11: 0.15116898 | AI11: =SUM(D11:AH11) | AJ11: 1.59125 | AK11: =AJ11-AI11
A12: CHIARA GOBBI MARIA | B12: GBBMCH73R57H501G | C12: L'ufficio digitale - Tecninf - Fondoconoscenza | AI12: =SUM(D12:AH12) | AK12: =AJ12-AI12
A13: LIMETTI ION | B13: LMTNIO94M03Z129S | C13: Big Data - Tecninf - Fondoconoscenza | H13: 0.1730787 | I13: 0.28488426 | J13: 0.051481481 | V13: 0.20497685 | AB13: 0.23744213 | AC13: 0.21349537 | AD13: 0.21792824 | AI13: =SUM(D13:AH13) | AJ13: 1.383287 | AK13: =AJ13-AI13
A14: LUCA' VERONICA | B14: LCUVNC85L52D976T | C14: Big Data - Tecninf - Fondoconoscenza | G14: 0.006400463 | H14: 0.016342593 | I14: 0.18077546 | J14: 0.099861111 | N14: 0.041481481 | P14: 0.10105324 | Q14: 0.0036921296 | AE14: 0.0021296296 | AI14: =SUM(D14:AH14) | AJ14: 0.48982639 | AK14: =AJ14-AI14 | AM14: 0.038090278
A15: MAGNANINI LORENZO | B15: MGNLNZ97M04H501T | C15: La programmazione - Tecninf - Fondoconoscenza | I15: 0.19108796 | J15: 0.12748843 | AI15: =SUM(D15:AH15) | AJ15: 0.31857639 | AK15: =AJ15-AI15
A16: MARIANI ALESSIA | B16: MRNLSS75L68H501L | C16: Big Data - Tecninf - Fondoconoscenza | I16: 0.31820602 | J16: 0.15923611 | K16: 0.06462963 | N16: 0.20925926 | P16: 0.10424769 | Q16: 0.095381944 | U16: 0.25689815 | V16: 0.051006944 | W16: 0.13597222 | X16: 0.12849537 | Y16: 0.048483796 | AB16: 0.23425926 | AC16: 0.010694444 | AD16: 0.2146875 | AF16: 0.06244213 | AI16: =SUM(D16:AH16) | AJ16: 2.0939005 | AK16: =AJ16-AI16
A17: MASCELLINO GIULIO | B17: MSCGLI83C04G511L | C17: Big Data - Tecninf - Fondoconoscenza | AI17: =SUM(D17:AH17) | AK17: =AJ17-AI17
A18: PACPACO MICHAEL DEPOLLY | B18: PCPMHL00R03H501G | C18: La programmazione - Tecninf - Fondoconoscenza | H18: 0.11987269 | I18: 0.13309028 | J18: 0.071689815 | K18: 0.049918981 | AI18: =SUM(D18:AH18) | AJ18: 0.37457176 | AK18: =AJ18-AI18
A19: PASSIO ROBERTA | B19: PSSRRT76L56H501O | C19: Sicurezza Informatica - Tecninf - Fondoconoscenza | AI19: =SUM(D19:AH19) | AK19: =AJ19-AI19
A20: PERILLA GIAN LEO GAMES | B20: PRLGLG98M18H501X | C20: Big Data - Tecninf - Fondoconoscenza | U20: 0.019594907 | V20: 0.019953704 | Y20: 0.036574074 | AB20: 0.028888889 | AC20: 0.042083333 | AE20: 0.010266204 | AF20: 0.030138889 | AI20: =SUM(D20:AH20) | AJ20: 0.20767361 | AK20: =AJ20-AI20 | AM20: 0.020173611
A21: PINNA ROBERTO CAO | B21: CPNRRT66D27H501V | C21: Project Management per il digitale - Tecninf - Fondoconoscenza | AI21: =SUM(D21:AH21) | AK21: =AJ21-AI21
A22: POGGI ROBERTO | B22: PGGRRT91H07F839Q | C22: Big Data - Tecninf - Fondoconoscenza | AI22: =SUM(D22:AH22) | AK22: =AJ22-AI22
A23: PRASAD RAKESH KUMAR | B23: PRSRSH87S19H501S | C23: Sicurezza Informatica - Tecninf - Fondoconoscenza | AI23: =SUM(D23:AH23) | AK23: =AJ23-AI23
A24: PUDDU RAIMONDO | B24: PDDRND75R08H501S | C24: Big Data - Tecninf - Fondoconoscenza | J24: 0.0084722222 | AF24: 0.015127315 | AI24: =SUM(D24:AH24) | AJ24: 0.025162037 | AK24: =AJ24-AI24 | AM24: 0.0015625
A25: RANIERI FRANCESCO | B25: RNRFNC99L28H501B | C25: La programmazione - Tecninf - Fondoconoscenza | G25: 0.080659722 | H25: 0.1562037 | K25: 0.08849537 | N25: 0.068136574 | O25: 0.072766204 | P25: 0.18259259 | U25: 0.026076389 | V25: 0.13278935 | W25: 0.027025463 | AC25: 0.07994213 | AD25: 0.060393519 | AE25: 0.019351852 | AF25: 0.090486111 | AI25: =SUM(D25:AH25) | AJ25: 1.084919 | AK25: =AJ25-AI25
